Workbook

Sheet Summary
A1: The EverBloom Center for Women: three-case summary
A2: Green = linked from the monthly sheets. Change inputs on the Assumptions and Capital tabs; everything here updates.
A3: Where women heal, rebuild and become.
A4: Metric ($) | B4: Conservative | C4: Base | D4: Upside
A5: Year 1 revenue | B5: =SUMIF('Conservative Monthly'!$F$5:$AO$5,1,'Conservative Monthly'!$F$22:$AO$22) -> 1701913.4 | C5: =SUMIF('Base Monthly'!$F$5:$AO$5,1,'Base Monthly'!$F$22:$AO$22) -> 2693492.4 | D5: =SUMIF('Upside Monthly'!$F$5:$AO$5,1,'Upside Monthly'!$F$22:$AO$22) -> 3804714.4
A6: Year 1 EBITDA | B6: =SUMIF('Conservative Monthly'!$F$5:$AO$5,1,'Conservative Monthly'!$F$46:$AO$46) -> -1483353.4 | C6: =SUMIF('Base Monthly'!$F$5:$AO$5,1,'Base Monthly'!$F$46:$AO$46) -> -523933.21 | D6: =SUMIF('Upside Monthly'!$F$5:$AO$5,1,'Upside Monthly'!$F$46:$AO$46) -> 559307.36
A7: Year 1 EBITDA margin | B7: =IF(B5=0,0,B6/B5) -> -0.87157984 | C7: =IF(C5=0,0,C6/C5) -> -0.19451817 | D7: =IF(D5=0,0,D6/D5) -> 0.14700377
A8: Year 1 net cash flow | B8: =SUMIF('Conservative Monthly'!$F$5:$AO$5,1,'Conservative Monthly'!$F$51:$AO$51) -> -3494342.5 | C8: =SUMIF('Base Monthly'!$F$5:$AO$5,1,'Base Monthly'!$F$51:$AO$51) -> -2907300.1 | D8: =SUMIF('Upside Monthly'!$F$5:$AO$5,1,'Upside Monthly'!$F$51:$AO$51) -> -2244087.5
A9: Year 2 revenue | B9: =SUMIF('Conservative Monthly'!$F$5:$AO$5,2,'Conservative Monthly'!$F$22:$AO$22) -> 5991113.8 | C9: =SUMIF('Base Monthly'!$F$5:$AO$5,2,'Base Monthly'!$F$22:$AO$22) -> 8512508.7 | D9: =SUMIF('Upside Monthly'!$F$5:$AO$5,2,'Upside Monthly'!$F$22:$AO$22) -> 11066665
A10: Year 2 EBITDA | B10: =SUMIF('Conservative Monthly'!$F$5:$AO$5,2,'Conservative Monthly'!$F$46:$AO$46) -> 1227960.5 | C10: =SUMIF('Base Monthly'!$F$5:$AO$5,2,'Base Monthly'!$F$46:$AO$46) -> 3713563 | D10: =SUMIF('Upside Monthly'!$F$5:$AO$5,2,'Upside Monthly'!$F$46:$AO$46) -> 6248932.8
A11: Year 2 EBITDA margin | B11: =IF(B9=0,0,B10/B9) -> 0.20496364 | C11: =IF(C9=0,0,C10/C9) -> 0.43624778 | D11: =IF(D9=0,0,D10/D9) -> 0.56466271
A12: Year 2 net cash flow | B12: =SUMIF('Conservative Monthly'!$F$5:$AO$5,2,'Conservative Monthly'!$F$51:$AO$51) -> 911840.67 | C12: =SUMIF('Base Monthly'!$F$5:$AO$5,2,'Base Monthly'!$F$51:$AO$51) -> 3326334.8 | D12: =SUMIF('Upside Monthly'!$F$5:$AO$5,2,'Upside Monthly'!$F$51:$AO$51) -> 5845050
A13: Year 3 revenue | B13: =SUMIF('Conservative Monthly'!$F$5:$AO$5,3,'Conservative Monthly'!$F$22:$AO$22) -> 6540486.8 | C13: =SUMIF('Base Monthly'!$F$5:$AO$5,3,'Base Monthly'!$F$22:$AO$22) -> 9245496.3 | D13: =SUMIF('Upside Monthly'!$F$5:$AO$5,3,'Upside Monthly'!$F$22:$AO$22) -> 11919855
A14: Year 3 EBITDA | B14: =SUMIF('Conservative Monthly'!$F$5:$AO$5,3,'Conservative Monthly'!$F$46:$AO$46) -> 1638062.1 | C14: =SUMIF('Base Monthly'!$F$5:$AO$5,3,'Base Monthly'!$F$46:$AO$46) -> 4308589.3 | D14: =SUMIF('Upside Monthly'!$F$5:$AO$5,3,'Upside Monthly'!$F$46:$AO$46) -> 6968973.9
A15: Year 3 EBITDA margin | B15: =IF(B13=0,0,B14/B13) -> 0.25044957 | C15: =IF(C13=0,0,C14/C13) -> 0.46602033 | D15: =IF(D13=0,0,D14/D13) -> 0.58465258
A16: Year 3 net cash flow | B16: =SUMIF('Conservative Monthly'!$F$5:$AO$5,3,'Conservative Monthly'!$F$51:$AO$51) -> 1572837.8 | C16: =SUMIF('Base Monthly'!$F$5:$AO$5,3,'Base Monthly'!$F$51:$AO$51) -> 4224745.5 | D16: =SUMIF('Upside Monthly'!$F$5:$AO$5,3,'Upside Monthly'!$F$51:$AO$51) -> 6864943.1
A18: Peak capital need | B18: ='Conservative Monthly'!B56 -> 3551434.9 | C18: ='Base Monthly'!B56 -> 2986131.8 | D18: ='Upside Monthly'!B56 -> 2758115.9
A19: Month of peak need | B19: ='Conservative Monthly'!B57 -> 14 | C19: ='Base Monthly'!B57 -> 11 | D19: ='Upside Monthly'!B57 -> 9
A20: EBITDA positive from month | B20: ='Conservative Monthly'!B58 -> 12 | C20: ='Base Monthly'!B58 -> 9 | D20: ='Upside Monthly'!B58 -> 7
A21: Cash flow positive from month | B21: ='Conservative Monthly'!B59 -> 15 | C21: ='Base Monthly'!B59 -> 12 | D21: ='Upside Monthly'!B59 -> 10
A22: Cumulative cash payback month | B22: ='Conservative Monthly'!B60 -> After M36 | C22: ='Base Monthly'!B60 -> 23 | D22: ='Upside Monthly'!B60 -> 18
A23: Cumulative cash at Month 36 | B23: ='Conservative Monthly'!B61 -> -1009664 | C23: ='Base Monthly'!B61 -> 4643780.1 | D23: ='Upside Monthly'!B61 -> 10465906
A25: Year 1 includes the five pre-opening months (Months 1-5); first patients in Month 6. Months count from project start.

Sheet Assumptions
A1: The EverBloom Center for Women: model assumptions
A2: Blue = input you can change. Black = formula. Yellow = key lever. Columns B-D feed the three monthly sheets. All figures are illustrative planning assumptions (source: management estimates), to be validated against payer contracts and the chosen site.
A4: Assumption | B4: Conservative | C4: Base | D4: Upside | E4: Notes
A5: Capacity and calendar
A6: Residential beds | B6: 20 | C6: =$B6 -> 20 | D6: =$B6 -> 20 | E6: Women-only residential
A7: Opening month (first admissions) | B7: 6 | C7: =$B7 -> 6 | D7: =$B7 -> 6 | E7: Months counted from project start / funding. Management has opened comparable Florida sites in 4 to 6 months
A8: Days per month | B8: 30.4 | C8: =$B8 -> 30.4 | D8: =$B8 -> 30.4
A9: PHP program days per month | B9: 21.7 | C9: =$B9 -> 21.7 | D9: =$B9 -> 21.7 | E9: About 5 days a week
A10: IOP program days per month | B10: 17.3 | C10: =$B10 -> 17.3 | D10: =$B10 -> 17.3 | E10: About 4 days a week
A11: Volumes and rates
A12: Residential rate per patient day | B12: 950 | C12: 1100 | D12: 1300 | E12: Blended net rate; upside reflects premium/luxury positioning
A13: Stabilized occupancy through Month 24 | B13: 0.72 | C13: 0.82 | D13: 0.85
A14: Stabilized occupancy from Month 25 | B14: 0.75 | C14: 0.85 | D14: 0.88
A15: PHP target average daily census | B15: 8 | C15: 12 | D15: 15
A16: PHP rate per patient day | B16: 475 | C16: 550 | D16: 625
A17: IOP target average daily census | B17: 10 | C17: 15 | D17: 20
A18: IOP rate per patient day | B18: 240 | C18: 275 | D18: 310
A19: Outpatient visits per month at target | B19: 120 | C19: 200 | D19: 280
A20: Outpatient rate per visit | B20: 150 | C20: =$B20 -> 150 | D20: =$B20 -> 150
A21: PHP starts (months after opening) | B21: 2 | C21: =$B21 -> 2 | D21: =$B21 -> 2
A22: PHP months to reach target | B22: 8 | C22: =$B22 -> 8 | D22: =$B22 -> 8
A23: IOP starts (months after opening) | B23: 3 | C23: =$B23 -> 3 | D23: =$B23 -> 3
A24: IOP months to reach target | B24: 9 | C24: =$B24 -> 9 | D24: =$B24 -> 9
A25: Outpatient starts (months after opening) | B25: 6 | C25: =$B25 -> 6 | D25: =$B25 -> 6
A26: Outpatient months to reach target | B26: 6 | C26: =$B26 -> 6 | D26: =$B26 -> 6
A27: Rate increase from Month 25 | B27: 0.03 | C27: =$B27 -> 0.03 | D27: =$B27 -> 0.03
A28: Cost inflation per year | B28: 0.03 | C28: =$B28 -> 0.03 | D28: =$B28 -> 0.03
A29: Collections (share of a month's billed revenue collected)
A30: Denials and bad debt reserve (% of billed revenue) | B30: 0.08 | C30: =$B30 -> 0.08 | D30: =$B30 -> 0.08 | E30: Claims that are denied, underpaid or never collected
A31: Collected same month | B31: 0 | C31: =$B31 -> 0 | D31: =$B31 -> 0
A32: Collected 1 month later | B32: 0.2 | C32: =$B32 -> 0.2 | D32: =$B32 -> 0.2
A33: Collected 2 months later | B33: 0.55 | C33: =$B33 -> 0.55 | D33: =$B33 -> 0.55 | E33: In-network contracts take 30-180+ days; OON PPO and self-pay from day one
A34: Collected 3 months later | B34: 0.25 | C34: =$B34 -> 0.25 | D34: =$B34 -> 0.25
A35: Payroll (roles, FTEs and rates live on the Staffing tab)
A36: Payroll taxes and benefits (% of wages) | B36: 0.22 | C36: =$B36 -> 0.22 | D36: =$B36 -> 0.22 | E36: FICA, FUTA/SUTA, workers comp, health benefits
A37: PRN, overtime and PTO coverage (% of payroll) | B37: 0.1 | C37: =$B37 -> 0.1 | D37: =$B37 -> 0.1 | E37: Lean 24/7 posts need fill-ins for sick days, PTO and turnover
A38: Operating expenses (monthly unless noted). Everything is in-house: no billing company, no marketing agency
A39: Facility rent once open | B39: 45000 | C39: =$B39 -> 45000 | D39: =$B39 -> 45000 | E39: Leased campus
A40: Pre-opening rent (% of full) | B40: 0.5 | C40: =$B40 -> 0.5 | D40: =$B40 -> 0.5
A41: Pre-opening rent start month | B41: 3 | C41: =$B41 -> 3 | D41: =$B41 -> 3 | E41: Half rent during buildout
...

Sheet Capital
A1: Startup capital: one-time costs by month, and uses of funds
A3: One-time cost ($) | B3: M1 | C3: M2 | D3: M3 | E3: M4 | F3: M5 | G3: M6 | H3: M7 | I3: M8 | J3: Total
A4: Security deposit | B4: 90000 | C4: 0 | D4: 0 | E4: 0 | F4: 0 | G4: 0 | H4: 0 | I4: 0 | J4: =SUM(B4:I4) -> 90000
A5: Buildout, life safety, ADA | B5: 0 | C5: 125000 | D5: 150000 | E5: 125000 | F5: 50000 | G5: 0 | H5: 0 | I5: 0 | J5: =SUM(B5:I5) -> 450000
A6: Furniture, fixtures and equipment | B6: 0 | C6: 0 | D6: 0 | E6: 100000 | F6: 175000 | G6: 0 | H6: 0 | I6: 0 | J6: =SUM(B6:I6) -> 275000
A7: Technology and EHR implementation | B7: 0 | C7: 0 | D7: 30000 | E7: 30000 | F7: 25000 | G7: 0 | H7: 0 | I7: 0 | J7: =SUM(B7:I7) -> 85000
A8: Licensing, accreditation and legal | B8: 30000 | C8: 20000 | D8: 20000 | E8: 20000 | F8: 15000 | G8: 15000 | H8: 0 | I8: 0 | J8: =SUM(B8:I8) -> 120000
A9: Credentialing and payer contracting | B9: 10000 | C9: 10000 | D9: 10000 | E9: 10000 | F9: 0 | G9: 0 | H9: 0 | I9: 0 | J9: =SUM(B9:I9) -> 40000
A10: Recruiting and training | B10: 0 | C10: 0 | D10: 15000 | E10: 20000 | F10: 25000 | G10: 0 | H10: 0 | I10: 0 | J10: =SUM(B10:I10) -> 60000
A11: Vehicles (2 transport vans) | B11: 0 | C11: 0 | D11: 0 | E11: 0 | F11: 80000 | G11: 0 | H11: 0 | I11: 0 | J11: =SUM(B11:I11) -> 80000
A12: Brand, website and launch marketing | B12: 15000 | C12: 20000 | D12: 20000 | E12: 20000 | F12: 0 | G12: 0 | H12: 0 | I12: 0 | J12: =SUM(B12:I12) -> 75000
A13: Total one-time costs | B13: =SUM(B4:B12) -> 145000 | C13: =SUM(C4:C12) -> 175000 | D13: =SUM(D4:D12) -> 245000 | E13: =SUM(E4:E12) -> 325000 | F13: =SUM(F4:F12) -> 370000 | G13: =SUM(G4:G12) -> 15000 | H13: =SUM(H4:H12) -> 0 | I13: =SUM(I4:I12) -> 0 | J13: =SUM(J4:J12) -> 1275000
A14: Source: management estimates for a leased 20-bed campus that needs light renovation, not new construction; a 4 to 6 month opening depends on finding that kind of property.
A16: Uses of funds (base case) | B16: $
A17: One-time startup costs (above) | B17: =J13 -> 1275000
A18: Pre-opening payroll and operations | B18: =SUMPRODUCT(('Base Monthly'!$F$6:$AO$6<0)*('Base Monthly'!$F$28:$AO$28+'Base Monthly'!$F$45:$AO$45)) -> 596790.1
A19: Ramp operating support and working capital | B19: ='Base Monthly'!B56-B17-B18 -> 1114341.7
A20: Reserve and contingency | B20: =B22-'Base Monthly'!B56 -> 513868.17
A21: Total uses | B21: =SUM(B17:B20) -> 3500000
A22: Equity raise (input) | B22: 3500000
A23: Recommended credit line (input) | B23: 500000
A24: Conservative case peak need | B24: ='Conservative Monthly'!B56 -> 3551434.9
A25: Raise + credit line covers conservative peak? | B25: =IF(B22+B23>=B24,"Yes","No") -> Yes

Sheet Staffing
A1: EverBloom lean staffing model: every role, FTE, Florida market rate and planned pay
A2: Lean and in-house: the corporate COO covers licensing, payers, HR, brand and content, and an onsite Administrator runs the site day to day; one RN (Director of Nursing) with LPNs on every shift; one psychiatric NP. Medical director stipend and contracted wellness services are operating expenses on the Assumptions tab. Market median = Florida statewide annual median, BLS OEWS 2025 via O*NET OnLine. Planned rate = management input (blue). Census-driven roles scale with patient volume but never drop below the minimum FTE.
A4: Department | B4: Role | C4: Staffing type | D4: FTE at stabilized census | E4: Minimum FTE | F4: Start month | G4: Market reference (BLS occupation) | H4: FL market median | I4: Planned annual rate | J4: Burden applies (1=yes) | K4: Coverage and notes | L4: Stabilized annual cost
A5: Leadership | B5: Chief Operating Officer (Ashlee Bryant), corporate | C5: Fixed | D5: 1 | F5: 1 | G5: Medical and health services managers | H5: 120360 | I5: 200000 | J5: 1 | K5: Everything above the site: licensing, payers, finance, HR, brand, content, compliance, growth | L5: =D5*I5*(1+Assumptions!$B$36*J5) -> 244000
A6: Leadership | B6: Facility Administrator (onsite) | C6: Fixed | D6: 1 | F6: 5 | G6: Medical and health services managers | H6: 120360 | I6: 85000 | J6: 1 | K6: Runs the site day to day: schedules, staff, patient and family issues, facility; starts 30 days before opening | L6: =D6*I6*(1+Assumptions!$B$36*J6) -> 103700
A7: Clinical leadership | B7: Clinical Director (LCSW / LMHC) | C7: Fixed | D7: 1 | F7: 3 | G7: Medical and health services managers | H7: 120360 | I7: 110000 | J7: 1 | K7: Runs the clinical program and the tiered curriculum; carries a small caseload | L7: =D7*I7*(1+Assumptions!$B$36*J7) -> 134200
A8: Clinical leadership | B8: Director of Nursing (RN) | C8: Fixed | D8: 1 | F8: 4 | G8: Registered nurses | H8: 84190 | I8: 105000 | J8: 1 | K8: The one RN: directs LPNs, on call nights and weekends | L8: =D8*I8*(1+Assumptions!$B$36*J8) -> 128100
A9: Clinical leadership | B9: Psychiatric Nurse Practitioner | C9: Fixed | D9: 1 | F9: 5 | G9: Nurse practitioners | H9: 129510 | I9: 135000 | J9: 1 | K9: All levels of care; Dr. Bokhari supervises as medical director | L9: =D9*I9*(1+Assumptions!$B$36*J9) -> 164700
A10: Nursing & floor | B10: Licensed Practical Nurse, 24/7 | C10: Fixed | D10: 4.2 | F10: 5 | G10: Licensed practical and vocational nurses | H10: 61770 | I10: 62000 | J10: 1 | K10: One LPN on site every shift: med pass, vitals, intake nursing, monitoring | L10: =D10*I10*(1+Assumptions!$B$36*J10) -> 317688
A11: Nursing & floor | B11: Behavioral Health Technician | C11: Fixed | D11: 6.3 | F11: 5 | G11: Psychiatric technicians | H11: 43570 | I11: 44000 | J11: 1 | K11: Two on 12-hour days, one awake overnight; trained in ED meal support; drive outings | L11: =D11*I11*(1+Assumptions!$B$36*J11) -> 338184
A12: Therapy & wellness | B12: Primary Therapist, residential (general and OCD) | C12: Residential | D12: 2 | E12: 1 | F12: 5 | G12: Mental health counselors | H12: 56790 | I12: 65000 | J12: 1 | K12: Caseload about 5 to 6; ERP-trained for the OCD track | L12: =D12*I12*(1+Assumptions!$B$36*J12) -> 158600
A13: Therapy & wellness | B13: Eating Disorder Therapist (specialty track) | C13: Fixed | D13: 1 | F13: 5 | G13: Mental health counselors | H13: 56790 | I13: 70000 | J13: 1 | K13: ED specialist (CEDS or working toward it); ED groups and individual therapy from day one | L13: =D13*I13*(1+Assumptions!$B$36*J13) -> 85400
A14: Therapy & wellness | B14: Day Program Therapist (PHP / IOP) | C14: Day program | D14: 2 | E14: 1 | F14: 8 | G14: Mental health counselors | H14: 56790 | I14: 65000 | J14: 1 | K14: Co-leads groups with wellness staff | L14: =D14*I14*(1+Assumptions!$B$36*J14) -> 158600
A15: Therapy & wellness | B15: Wellness & Movement Coordinator | C15: Fixed | D15: 1 | F15: 5 | G15: Recreational therapists | H15: 57980 | I15: 55000 | J15: 1 | K15: Yoga, fitness, recreation, nature outings | L15: =D15*I15*(1+Assumptions!$B$36*J15) -> 67100
A16: Therapy & wellness | B16: Art / Expressive Therapist (part-time) | C16: Fixed | D16: 0.5 | F16: 5 | G16: Recreational therapists | H16: 57980 | I16: 58000 | J16: 1 | K16: Art and expressive groups | L16: =D16*I16*(1+Assumptions!$B$36*J16) -> 35380
A17: Therapy & wellness | B17: Registered Dietitian | C17: Fixed | D17: 1 | F17: 5 | G17: Dietitians and nutritionists | H17: 76050 | I17: 76000 | J17: 1 | K17: ED track from day one: meal plans, nutrition therapy, menus and cooking groups | L17: =D17*I17*(1+Assumptions!$B$36*J17) -> 92720
A18: Admissions & business | B18: Case Manager / Utilization Review (licensed) | C18: Fixed | D18: 1 | F18: 5 | G18: Mental health counselors | H18: 56790 | I18: 60000 | J18: 1 | K18: Authorizations, concurrent review, discharge planning | L18: =D18*I18*(1+Assumptions!$B$36*J18) -> 73200
A19: Admissions & business | B19: Admissions & Verification Coordinator | C19: Fixed | D19: 1.5 | F19: 5 | G19: Customer service representatives | H19: 40440 | I19: 46000 | J19: 1 | K19: Calls 7 days and benefits checks; after-hours calls to an on-call phone | L19: =D19*I19*(1+Assumptions!$B$36*J19) -> 84180
A20: Admissions & business | B20: Billing & Revenue Cycle Specialist | C20: Fixed | D20: 1 | F20: 5 | G20: Billing and posting clerks | H20: 46540 | I20: 55000 | J20: 1 | K20: Claims, posting, denials, A/R; in-house | L20: =D20*I20*(1+Assumptions!$B$36*J20) -> 67100
A21: Admissions & business | B21: Outreach & Digital Marketing Manager | C21: Fixed | D21: 1 | F21: 3 | G21: Sales representatives of services | H21: 60660 | I21: 70000 | J21: 1 | K21: Referral partners plus Google and Meta ads | L21: =D21*I21*(1+Assumptions!$B$36*J21) -> 85400
A22: Support services | B22: Cook | C22: Fixed | D22: 1.5 | F22: 5 | G22: Cooks, institution and cafeteria | H22: 36250 | I22: 38000 | J22: 1 | K22: Meals 7 days; ED meal plans with the dietitian | L22: =D22*I22*(1+Assumptions!$B$36*J22) -> 69540
A23: Support services | B23: Housekeeper | C23: Fixed | D23: 1 | F23: 5 | G23: Maids and housekeeping cleaners | H23: 33860 | I23: 35000 | J23: 1 | K23: Above Florida $15/hr minimum wage (Sept 2026) | L23: =D23*I23*(1+Assumptions!$B$36*J23) -> 42700
A24: Total at stabilized census | D24: =SUM(D5:D23) -> 30 | K24: Includes payroll taxes and benefits | L24: =SUM(L5:L23) -> 2450492
A26: Summary by department
A27: Department | B27: FTEs | C27: Stabilized annual cost incl. burden | D27: Share of payroll
A28: Leadership | B28: =SUMIF($A$5:$A$23,A28,$D$5:$D$23) -> 2 | C28: =SUMIF($A$5:$A$23,A28,$L$5:$L$23) -> 347700 | D28: =IF($L$24=0,0,C28/$L$24) -> 0.14188987
A29: Clinical leadership | B29: =SUMIF($A$5:$A$23,A29,$D$5:$D$23) -> 3 | C29: =SUMIF($A$5:$A$23,A29,$L$5:$L$23) -> 427000 | D29: =IF($L$24=0,0,C29/$L$24) -> 0.17425072
A30: Nursing & floor | B30: =SUMIF($A$5:$A$23,A30,$D$5:$D$23) -> 10.5 | C30: =SUMIF($A$5:$A$23,A30,$L$5:$L$23) -> 655872 | D30: =IF($L$24=0,0,C30/$L$24) -> 0.26764911
A31: Therapy & wellness | B31: =SUMIF($A$5:$A$23,A31,$D$5:$D$23) -> 7.5 | C31: =SUMIF($A$5:$A$23,A31,$L$5:$L$23) -> 597800 | D31: =IF($L$24=0,0,C31/$L$24) -> 0.24395101
A32: Admissions & business | B32: =SUMIF($A$5:$A$23,A32,$D$5:$D$23) -> 4.5 | C32: =SUMIF($A$5:$A$23,A32,$L$5:$L$23) -> 309880 | D32: =IF($L$24=0,0,C32/$L$24) -> 0.12645624
A33: Support services | B33: =SUMIF($A$5:$A$23,A33,$D$5:$D$23) -> 2.5 | C33: =SUMIF($A$5:$A$23,A33,$L$5:$L$23) -> 112240 | D33: =IF($L$24=0,0,C33/$L$24) -> 0.045803047
A34: Total | B34: =SUM(B28:B33) -> 30 | C34: =SUM(C28:C33) -> 2450492
A36: Sources: Florida statewide annual median wages, BLS Occupational Employment and Wage Statistics 2025, via O*NET OnLine (onetonline.org/link/localwages, st=FL). 24/7 posts use 4.2 FTE (8,760 hours / 2,080). Census-driven FTEs = stabilized FTE x (census / target census), never below the minimum.

Sheet Conservative Monthly
A1: EverBloom: monthly model, Conservative case
A2: All values in $ unless noted. Columns C-E are blank padding so collection lags work in the first months.
C3: (pad) | D3: (pad) | E3: (pad)
A4: Month | F4: 1 | G4: 2 | H4: 3 | I4: 4 | J4: 5 | K4: 6 | L4: 7 | M4: 8 | N4: 9 | O4: 10 | P4: 11 | Q4: 12 | R4: 13 | S4: 14 | T4: 15 | U4: 16 | V4: 17 | W4: 18 | X4: 19 | Y4: 20 | Z4: 21 | AA4: 22 | AB4: 23 | AC4: 24 | AD4: 25 | AE4: 26 | AF4: 27 | AG4: 28 | AH4: 29 | AI4: 30 | AJ4: 31 | AK4: 32 | AL4: 33 | AM4: 34 | AN4: 35 | AO4: 36
A5: Year | F5: =ROUNDUP(F4/12,0) -> 1 | G5: =ROUNDUP(G4/12,0) -> 1 | H5: =ROUNDUP(H4/12,0) -> 1 | I5: =ROUNDUP(I4/12,0) -> 1 | J5: =ROUNDUP(J4/12,0) -> 1 | K5: =ROUNDUP(K4/12,0) -> 1 | L5: =ROUNDUP(L4/12,0) -> 1 | M5: =ROUNDUP(M4/12,0) -> 1 | ... AO5: =ROUNDUP(AO4/12,0) -> 3
A6: Months since opening | F6: =F4-Assumptions!$B$7 -> -5 | G6: =G4-Assumptions!$B$7 -> -4 | H6: =H4-Assumptions!$B$7 -> -3 | I6: =I4-Assumptions!$B$7 -> -2 | J6: =J4-Assumptions!$B$7 -> -1 | K6: =K4-Assumptions!$B$7 -> 0 | L6: =L4-Assumptions!$B$7 -> 1 | M6: =M4-Assumptions!$B$7 -> 2 | ... AO6: =AO4-Assumptions!$B$7 -> 30
A7: Cost escalator | F7: =(1+Assumptions!$B$28)^(F5-1) -> 1 | G7: =(1+Assumptions!$B$28)^(G5-1) -> 1 | H7: =(1+Assumptions!$B$28)^(H5-1) -> 1 | I7: =(1+Assumptions!$B$28)^(I5-1) -> 1 | J7: =(1+Assumptions!$B$28)^(J5-1) -> 1 | K7: =(1+Assumptions!$B$28)^(K5-1) -> 1 | L7: =(1+Assumptions!$B$28)^(L5-1) -> 1 | M7: =(1+Assumptions!$B$28)^(M5-1) -> 1 | ... AO7: =(1+Assumptions!$B$28)^(AO5-1) -> 1.0609
A8: Rate escalator | F8: =IF(F4>24,1+Assumptions!$B$27,1) -> 1 | G8: =IF(G4>24,1+Assumptions!$B$27,1) -> 1 | H8: =IF(H4>24,1+Assumptions!$B$27,1) -> 1 | I8: =IF(I4>24,1+Assumptions!$B$27,1) -> 1 | J8: =IF(J4>24,1+Assumptions!$B$27,1) -> 1 | K8: =IF(K4>24,1+Assumptions!$B$27,1) -> 1 | L8: =IF(L4>24,1+Assumptions!$B$27,1) -> 1 | M8: =IF(M4>24,1+Assumptions!$B$27,1) -> 1 | ... AO8: =IF(AO4>24,1+Assumptions!$B$27,1) -> 1.03
A9: VOLUMES
A10: Residential occupancy | F10: =IF(F6<0,0,IF(F6<11,INDEX(Assumptions!$B$69:$B$79,F6+1),IF(F4>24,Assumptions!$B$14,Assumptions!$B$13))) -> 0 | G10: =IF(G6<0,0,IF(G6<11,INDEX(Assumptions!$B$69:$B$79,G6+1),IF(G4>24,Assumptions!$B$14,Assumptions!$B$13))) -> 0 | H10: =IF(H6<0,0,IF(H6<11,INDEX(Assumptions!$B$69:$B$79,H6+1),IF(H4>24,Assumptions!$B$14,Assumptions!$B$13))) -> 0 | I10: =IF(I6<0,0,IF(I6<11,INDEX(Assumptions!$B$69:$B$79,I6+1),IF(I4>24,Assumptions!$B$14,Assumptions!$B$13))) -> 0 | J10: =IF(J6<0,0,IF(J6<11,INDEX(Assumptions!$B$69:$B$79,J6+1),IF(J4>24,Assumptions!$B$14,Assumptions!$B$13))) -> 0 | K10: =IF(K6<0,0,IF(K6<11,INDEX(Assumptions!$B$69:$B$79,K6+1),IF(K4>24,Assumptions!$B$14,Assumptions!$B$13))) -> 0.15 | L10: =IF(L6<0,0,IF(L6<11,INDEX(Assumptions!$B$69:$B$79,L6+1),IF(L4>24,Assumptions!$B$14,Assumptions!$B$13))) -> 0.25 | M10: =IF(M6<0,0,IF(M6<11,INDEX(Assumptions!$B$69:$B$79,M6+1),IF(M4>24,Assumptions!$B$14,Assumptions!$B$13))) -> 0.35 | ... AO10: =IF(AO6<0,0,IF(AO6<11,INDEX(Assumptions!$B$69:$B$79,AO6+1),IF(AO4>24,Assumptions!$B$14,Assumptions!$B$13))) -> 0.75
A11: Residential patient days | F11: =Assumptions!$B$6*F10*Assumptions!$B$8 -> 0 | G11: =Assumptions!$B$6*G10*Assumptions!$B$8 -> 0 | H11: =Assumptions!$B$6*H10*Assumptions!$B$8 -> 0 | I11: =Assumptions!$B$6*I10*Assumptions!$B$8 -> 0 | J11: =Assumptions!$B$6*J10*Assumptions!$B$8 -> 0 | K11: =Assumptions!$B$6*K10*Assumptions!$B$8 -> 91.2 | L11: =Assumptions!$B$6*L10*Assumptions!$B$8 -> 152 | M11: =Assumptions!$B$6*M10*Assumptions!$B$8 -> 212.8 | ... AO11: =Assumptions!$B$6*AO10*Assumptions!$B$8 -> 456
A12: PHP average daily census | F12: =IF(F6-Assumptions!$B$21<0,0,Assumptions!$B$15*MIN(1,(F6-Assumptions!$B$21+1)/Assumptions!$B$22)) -> 0 | G12: =IF(G6-Assumptions!$B$21<0,0,Assumptions!$B$15*MIN(1,(G6-Assumptions!$B$21+1)/Assumptions!$B$22)) -> 0 | H12: =IF(H6-Assumptions!$B$21<0,0,Assumptions!$B$15*MIN(1,(H6-Assumptions!$B$21+1)/Assumptions!$B$22)) -> 0 | I12: =IF(I6-Assumptions!$B$21<0,0,Assumptions!$B$15*MIN(1,(I6-Assumptions!$B$21+1)/Assumptions!$B$22)) -> 0 | J12: =IF(J6-Assumptions!$B$21<0,0,Assumptions!$B$15*MIN(1,(J6-Assumptions!$B$21+1)/Assumptions!$B$22)) -> 0 | K12: =IF(K6-Assumptions!$B$21<0,0,Assumptions!$B$15*MIN(1,(K6-Assumptions!$B$21+1)/Assumptions!$B$22)) -> 0 | L12: =IF(L6-Assumptions!$B$21<0,0,Assumptions!$B$15*MIN(1,(L6-Assumptions!$B$21+1)/Assumptions!$B$22)) -> 0 | M12: =IF(M6-Assumptions!$B$21<0,0,Assumptions!$B$15*MIN(1,(M6-Assumptions!$B$21+1)/Assumptions!$B$22)) -> 1 | ... AO12: =IF(AO6-Assumptions!$B$21<0,0,Assumptions!$B$15*MIN(1,(AO6-Assumptions!$B$21+1)/Assumptions!$B$22)) -> 8
A13: IOP average daily census | F13: =IF(F6-Assumptions!$B$23<0,0,Assumptions!$B$17*MIN(1,(F6-Assumptions!$B$23+1)/Assumptions!$B$24)) -> 0 | G13: =IF(G6-Assumptions!$B$23<0,0,Assumptions!$B$17*MIN(1,(G6-Assumptions!$B$23+1)/Assumptions!$B$24)) -> 0 | H13: =IF(H6-Assumptions!$B$23<0,0,Assumptions!$B$17*MIN(1,(H6-Assumptions!$B$23+1)/Assumptions!$B$24)) -> 0 | I13: =IF(I6-Assumptions!$B$23<0,0,Assumptions!$B$17*MIN(1,(I6-Assumptions!$B$23+1)/Assumptions!$B$24)) -> 0 | J13: =IF(J6-Assumptions!$B$23<0,0,Assumptions!$B$17*MIN(1,(J6-Assumptions!$B$23+1)/Assumptions!$B$24)) -> 0 | K13: =IF(K6-Assumptions!$B$23<0,0,Assumptions!$B$17*MIN(1,(K6-Assumptions!$B$23+1)/Assumptions!$B$24)) -> 0 | L13: =IF(L6-Assumptions!$B$23<0,0,Assumptions!$B$17*MIN(1,(L6-Assumptions!$B$23+1)/Assumptions!$B$24)) -> 0 | M13: =IF(M6-Assumptions!$B$23<0,0,Assumptions!$B$17*MIN(1,(M6-Assumptions!$B$23+1)/Assumptions!$B$24)) -> 0 | ... AO13: =IF(AO6-Assumptions!$B$23<0,0,Assumptions!$B$17*MIN(1,(AO6-Assumptions!$B$23+1)/Assumptions!$B$24)) -> 10
A14: Outpatient visits | F14: =IF(F6-Assumptions!$B$25<0,0,Assumptions!$B$19*MIN(1,(F6-Assumptions!$B$25+1)/Assumptions!$B$26)) -> 0 | G14: =IF(G6-Assumptions!$B$25<0,0,Assumptions!$B$19*MIN(1,(G6-Assumptions!$B$25+1)/Assumptions!$B$26)) -> 0 | H14: =IF(H6-Assumptions!$B$25<0,0,Assumptions!$B$19*MIN(1,(H6-Assumptions!$B$25+1)/Assumptions!$B$26)) -> 0 | I14: =IF(I6-Assumptions!$B$25<0,0,Assumptions!$B$19*MIN(1,(I6-Assumptions!$B$25+1)/Assumptions!$B$26)) -> 0 | J14: =IF(J6-Assumptions!$B$25<0,0,Assumptions!$B$19*MIN(1,(J6-Assumptions!$B$25+1)/Assumptions!$B$26)) -> 0 | K14: =IF(K6-Assumptions!$B$25<0,0,Assumptions!$B$19*MIN(1,(K6-Assumptions!$B$25+1)/Assumptions!$B$26)) -> 0 | L14: =IF(L6-Assumptions!$B$25<0,0,Assumptions!$B$19*MIN(1,(L6-Assumptions!$B$25+1)/Assumptions!$B$26)) -> 0 | M14: =IF(M6-Assumptions!$B$25<0,0,Assumptions!$B$19*MIN(1,(M6-Assumptions!$B$25+1)/Assumptions!$B$26)) -> 0 | ... AO14: =IF(AO6-Assumptions!$B$25<0,0,Assumptions!$B$19*MIN(1,(AO6-Assumptions!$B$25+1)/Assumptions!$B$26)) -> 120
A15: REVENUE (billed, net of contractual adjustments)
A16: Residential | F16: =F11*Assumptions!$B$12*F8 -> 0 | G16: =G11*Assumptions!$B$12*G8 -> 0 | H16: =H11*Assumptions!$B$12*H8 -> 0 | I16: =I11*Assumptions!$B$12*I8 -> 0 | J16: =J11*Assumptions!$B$12*J8 -> 0 | K16: =K11*Assumptions!$B$12*K8 -> 86640 | L16: =L11*Assumptions!$B$12*L8 -> 144400 | M16: =M11*Assumptions!$B$12*M8 -> 202160 | ... AO16: =AO11*Assumptions!$B$12*AO8 -> 446196
A17: PHP | F17: =F12*Assumptions!$B$9*Assumptions!$B$16*F8 -> 0 | G17: =G12*Assumptions!$B$9*Assumptions!$B$16*G8 -> 0 | H17: =H12*Assumptions!$B$9*Assumptions!$B$16*H8 -> 0 | I17: =I12*Assumptions!$B$9*Assumptions!$B$16*I8 -> 0 | J17: =J12*Assumptions!$B$9*Assumptions!$B$16*J8 -> 0 | K17: =K12*Assumptions!$B$9*Assumptions!$B$16*K8 -> 0 | L17: =L12*Assumptions!$B$9*Assumptions!$B$16*L8 -> 0 | M17: =M12*Assumptions!$B$9*Assumptions!$B$16*M8 -> 10307.5 | ... AO17: =AO12*Assumptions!$B$9*Assumptions!$B$16*AO8 -> 84933.8
A18: IOP | F18: =F13*Assumptions!$B$10*Assumptions!$B$18*F8 -> 0 | G18: =G13*Assumptions!$B$10*Assumptions!$B$18*G8 -> 0 | H18: =H13*Assumptions!$B$10*Assumptions!$B$18*H8 -> 0 | I18: =I13*Assumptions!$B$10*Assumptions!$B$18*I8 -> 0 | J18: =J13*Assumptions!$B$10*Assumptions!$B$18*J8 -> 0 | K18: =K13*Assumptions!$B$10*Assumptions!$B$18*K8 -> 0 | L18: =L13*Assumptions!$B$10*Assumptions!$B$18*L8 -> 0 | M18: =M13*Assumptions!$B$10*Assumptions!$B$18*M8 -> 0 | ... AO18: =AO13*Assumptions!$B$10*Assumptions!$B$18*AO8 -> 42765.6
A19: Outpatient | F19: =F14*Assumptions!$B$20*F8 -> 0 | G19: =G14*Assumptions!$B$20*G8 -> 0 | H19: =H14*Assumptions!$B$20*H8 -> 0 | I19: =I14*Assumptions!$B$20*I8 -> 0 | J19: =J14*Assumptions!$B$20*J8 -> 0 | K19: =K14*Assumptions!$B$20*K8 -> 0 | L19: =L14*Assumptions!$B$20*L8 -> 0 | M19: =M14*Assumptions!$B$20*M8 -> 0 | ... AO19: =AO14*Assumptions!$B$20*AO8 -> 18540
A20: Gross billed revenue | F20: =SUM(F16:F19) -> 0 | G20: =SUM(G16:G19) -> 0 | H20: =SUM(H16:H19) -> 0 | I20: =SUM(I16:I19) -> 0 | J20: =SUM(J16:J19) -> 0 | K20: =SUM(K16:K19) -> 86640 | L20: =SUM(L16:L19) -> 144400 | M20: =SUM(M16:M19) -> 212467.5 | ... AO20: =SUM(AO16:AO19) -> 592435.4
A21: Less denials and bad debt | F21: =-F20*Assumptions!$B$30 -> 0 | G21: =-G20*Assumptions!$B$30 -> 0 | H21: =-H20*Assumptions!$B$30 -> 0 | I21: =-I20*Assumptions!$B$30 -> 0 | J21: =-J20*Assumptions!$B$30 -> 0 | K21: =-K20*Assumptions!$B$30 -> -6931.2 | L21: =-L20*Assumptions!$B$30 -> -11552 | M21: =-M20*Assumptions!$B$30 -> -16997.4 | ... AO21: =-AO20*Assumptions!$B$30 -> -47394.832
A22: Net revenue | C22: 0 | D22: 0 | E22: 0 | F22: =F20+F21 -> 0 | G22: =G20+G21 -> 0 | H22: =H20+H21 -> 0 | I22: =I20+I21 -> 0 | J22: =J20+J21 -> 0 | K22: =K20+K21 -> 79708.8 | L22: =L20+L21 -> 132848 | M22: =M20+M21 -> 195470.1 | ... AO22: =AO20+AO21 -> 545040.57
A23: PAYROLL
A24: Fixed roles (leadership, RCM, admissions, marketing, nursing, support) | F24: =SUMPRODUCT((Staffing!$F$5:$F$23<=F4)*(Staffing!$C$5:$C$23="Fixed")*Staffing!$D$5:$D$23*Staffing!$I$5:$I$23*(1+Assumptions!$B$36*Staffing!$J$5:$J$23))/12 -> 20333.333 | G24: =SUMPRODUCT((Staffing!$F$5:$F$23<=G4)*(Staffing!$C$5:$C$23="Fixed")*Staffing!$D$5:$D$23*Staffing!$I$5:$I$23*(1+Assumptions!$B$36*Staffing!$J$5:$J$23))/12 -> 20333.333 | H24: =SUMPRODUCT((Staffing!$F$5:$F$23<=H4)*(Staffing!$C$5:$C$23="Fixed")*Staffing!$D$5:$D$23*Staffing!$I$5:$I$23*(1+Assumptions!$B$36*Staffing!$J$5:$J$23))/12 -> 38633.333 | I24: =SUMPRODUCT((Staffing!$F$5:$F$23<=I4)*(Staffing!$C$5:$C$23="Fixed")*Staffing!$D$5:$D$23*Staffing!$I$5:$I$23*(1+Assumptions!$B$36*Staffing!$J$5:$J$23))/12 -> 49308.333 | J24: =SUMPRODUCT((Staffing!$F$5:$F$23<=J4)*(Staffing!$C$5:$C$23="Fixed")*Staffing!$D$5:$D$23*Staffing!$I$5:$I$23*(1+Assumptions!$B$36*Staffing!$J$5:$J$23))/12 -> 177774.33 | K24: =SUMPRODUCT((Staffing!$F$5:$F$23<=K4)*(Staffing!$C$5:$C$23="Fixed")*Staffing!$D$5:$D$23*Staffing!$I$5:$I$23*(1+Assumptions!$B$36*Staffing!$J$5:$J$23))/12 -> 177774.33 | L24: =SUMPRODUCT((Staffing!$F$5:$F$23<=L4)*(Staffing!$C$5:$C$23="Fixed")*Staffing!$D$5:$D$23*Staffing!$I$5:$I$23*(1+Assumptions!$B$36*Staffing!$J$5:$J$23))/12 -> 177774.33 | M24: =SUMPRODUCT((Staffing!$F$5:$F$23<=M4)*(Staffing!$C$5:$C$23="Fixed")*Staffing!$D$5:$D$23*Staffing!$I$5:$I$23*(1+Assumptions!$B$36*Staffing!$J$5:$J$23))/12 -> 177774.33 | ... AO24: =SUMPRODUCT((Staffing!$F$5:$F$23<=AO4)*(Staffing!$C$5:$C$23="Fixed")*Staffing!$D$5:$D$23*Staffing!$I$5:$I$23*(1+Assumptions!$B$36*Staffing!$J$5:$J$23))/12 -> 177774.33
A25: Residential census-driven roles (techs, therapists) | F25: =SUMPRODUCT((Staffing!$F$5:$F$23<=F4)*(Staffing!$C$5:$C$23="Residential")*((Staffing!$D$5:$D$23*(F10/Assumptions!$B$13)+Staffing!$E$5:$E$23+ABS(Staffing!$D$5:$D$23*(F10/Assumptions!$B$13)-Staffing!$E$5:$E$23))/2)*Staffing!$I$5:$I$23*(1+Assumptions!$B$36*Staffing!$J$5:$J$23))/12 -> 0 | G25: =SUMPRODUCT((Staffing!$F$5:$F$23<=G4)*(Staffing!$C$5:$C$23="Residential")*((Staffing!$D$5:$D$23*(G10/Assumptions!$B$13)+Staffing!$E$5:$E$23+ABS(Staffing!$D$5:$D$23*(G10/Assumptions!$B$13)-Staffing!$E$5:$E$23))/2)*Staffing!$I$5:$I$23*(1+Assumptions!$B$36*Staffing!$J$5:$J$23))/12 -> 0 | H25: =SUMPRODUCT((Staffing!$F$5:$F$23<=H4)*(Staffing!$C$5:$C$23="Residential")*((Staffing!$D$5:$D$23*(H10/Assumptions!$B$13)+Staffing!$E$5:$E$23+ABS(Staffing!$D$5:$D$23*(H10/Assumptions!$B$13)-Staffing!$E$5:$E$23))/2)*Staffing!$I$5:$I$23*(1+Assumptions!$B$36*Staffing!$J$5:$J$23))/12 -> 0 | I25: =SUMPRODUCT((Staffing!$F$5:$F$23<=I4)*(Staffing!$C$5:$C$23="Residential")*((Staffing!$D$5:$D$23*(I10/Assumptions!$B$13)+Staffing!$E$5:$E$23+ABS(Staffing!$D$5:$D$23*(I10/Assumptions!$B$13)-Staffing!$E$5:$E$23))/2)*Staffing!$I$5:$I$23*(1+Assumptions!$B$36*Staffing!$J$5:$J$23))/12 -> 0 | J25: =SUMPRODUCT((Staffing!$F$5:$F$23<=J4)*(Staffing!$C$5:$C$23="Residential")*((Staffing!$D$5:$D$23*(J10/Assumptions!$B$13)+Staffing!$E$5:$E$23+ABS(Staffing!$D$5:$D$23*(J10/Assumptions!$B$13)-Staffing!$E$5:$E$23))/2)*Staffing!$I$5:$I$23*(1+Assumptions!$B$36*Staffing!$J$5:$J$23))/12 -> 6608.3333 | K25: =SUMPRODUCT((Staffing!$F$5:$F$23<=K4)*(Staffing!$C$5:$C$23="Residential")*((Staffing!$D$5:$D$23*(K10/Assumptions!$B$13)+Staffing!$E$5:$E$23+ABS(Staffing!$D$5:$D$23*(K10/Assumptions!$B$13)-Staffing!$E$5:$E$23))/2)*Staffing!$I$5:$I$23*(1+Assumptions!$B$36*Staffing!$J$5:$J$23))/12 -> 6608.3333 | L25: =SUMPRODUCT((Staffing!$F$5:$F$23<=L4)*(Staffing!$C$5:$C$23="Residential")*((Staffing!$D$5:$D$23*(L10/Assumptions!$B$13)+Staffing!$E$5:$E$23+ABS(Staffing!$D$5:$D$23*(L10/Assumptions!$B$13)-Staffing!$E$5:$E$23))/2)*Staffing!$I$5:$I$23*(1+Assumptions!$B$36*Staffing!$J$5:$J$23))/12 -> 6608.3333 | M25: =SUMPRODUCT((Staffing!$F$5:$F$23<=M4)*(Staffing!$C$5:$C$23="Residential")*((Staffing!$D$5:$D$23*(M10/Assumptions!$B$13)+Staffing!$E$5:$E$23+ABS(Staffing!$D$5:$D$23*(M10/Assumptions!$B$13)-Staffing!$E$5:$E$23))/2)*Staffing!$I$5:$I$23*(1+Assumptions!$B$36*Staffing!$J$5:$J$23))/12 -> 6608.3333 | ... AO25: =SUMPRODUCT((Staffing!$F$5:$F$23<=AO4)*(Staffing!$C$5:$C$23="Residential")*((Staffing!$D$5:$D$23*(AO10/Assumptions!$B$13)+Staffing!$E$5:$E$23+ABS(Staffing!$D$5:$D$23*(AO10/Assumptions!$B$13)-Staffing!$E$5:$E$23))/2)*Staffing!$I$5:$I$23*(1+Assumptions!$B$36*Staffing!$J$5:$J$23))/12 -> 13767.361
A26: Day program census-driven roles | F26: =SUMPRODUCT((Staffing!$F$5:$F$23<=F4)*(Staffing!$C$5:$C$23="Day program")*((Staffing!$D$5:$D$23*((F12+F13)/(Assumptions!$B$15+Assumptions!$B$17))+Staffing!$E$5:$E$23+ABS(Staffing!$D$5:$D$23*((F12+F13)/(Assumptions!$B$15+Assumptions!$B$17))-Staffing!$E$5:$E$23))/2)*Staffing!$I$5:$I$23*(1+Assumptions!$B$36*Staffing!$J$5:$J$23))/12 -> 0 | G26: =SUMPRODUCT((Staffing!$F$5:$F$23<=G4)*(Staffing!$C$5:$C$23="Day program")*((Staffing!$D$5:$D$23*((G12+G13)/(Assumptions!$B$15+Assumptions!$B$17))+Staffing!$E$5:$E$23+ABS(Staffing!$D$5:$D$23*((G12+G13)/(Assumptions!$B$15+Assumptions!$B$17))-Staffing!$E$5:$E$23))/2)*Staffing!$I$5:$I$23*(1+Assumptions!$B$36*Staffing!$J$5:$J$23))/12 -> 0 | H26: =SUMPRODUCT((Staffing!$F$5:$F$23<=H4)*(Staffing!$C$5:$C$23="Day program")*((Staffing!$D$5:$D$23*((H12+H13)/(Assumptions!$B$15+Assumptions!$B$17))+Staffing!$E$5:$E$23+ABS(Staffing!$D$5:$D$23*((H12+H13)/(Assumptions!$B$15+Assumptions!$B$17))-Staffing!$E$5:$E$23))/2)*Staffing!$I$5:$I$23*(1+Assumptions!$B$36*Staffing!$J$5:$J$23))/12 -> 0 | I26: =SUMPRODUCT((Staffing!$F$5:$F$23<=I4)*(Staffing!$C$5:$C$23="Day program")*((Staffing!$D$5:$D$23*((I12+I13)/(Assumptions!$B$15+Assumptions!$B$17))+Staffing!$E$5:$E$23+ABS(Staffing!$D$5:$D$23*((I12+I13)/(Assumptions!$B$15+Assumptions!$B$17))-Staffing!$E$5:$E$23))/2)*Staffing!$I$5:$I$23*(1+Assumptions!$B$36*Staffing!$J$5:$J$23))/12 -> 0 | J26: =SUMPRODUCT((Staffing!$F$5:$F$23<=J4)*(Staffing!$C$5:$C$23="Day program")*((Staffing!$D$5:$D$23*((J12+J13)/(Assumptions!$B$15+Assumptions!$B$17))+Staffing!$E$5:$E$23+ABS(Staffing!$D$5:$D$23*((J12+J13)/(Assumptions!$B$15+Assumptions!$B$17))-Staffing!$E$5:$E$23))/2)*Staffing!$I$5:$I$23*(1+Assumptions!$B$36*Staffing!$J$5:$J$23))/12 -> 0 | K26: =SUMPRODUCT((Staffing!$F$5:$F$23<=K4)*(Staffing!$C$5:$C$23="Day program")*((Staffing!$D$5:$D$23*((K12+K13)/(Assumptions!$B$15+Assumptions!$B$17))+Staffing!$E$5:$E$23+ABS(Staffing!$D$5:$D$23*((K12+K13)/(Assumptions!$B$15+Assumptions!$B$17))-Staffing!$E$5:$E$23))/2)*Staffing!$I$5:$I$23*(1+Assumptions!$B$36*Staffing!$J$5:$J$23))/12 -> 0 | L26: =SUMPRODUCT((Staffing!$F$5:$F$23<=L4)*(Staffing!$C$5:$C$23="Day program")*((Staffing!$D$5:$D$23*((L12+L13)/(Assumptions!$B$15+Assumptions!$B$17))+Staffing!$E$5:$E$23+ABS(Staffing!$D$5:$D$23*((L12+L13)/(Assumptions!$B$15+Assumptions!$B$17))-Staffing!$E$5:$E$23))/2)*Staffing!$I$5:$I$23*(1+Assumptions!$B$36*Staffing!$J$5:$J$23))/12 -> 0 | M26: =SUMPRODUCT((Staffing!$F$5:$F$23<=M4)*(Staffing!$C$5:$C$23="Day program")*((Staffing!$D$5:$D$23*((M12+M13)/(Assumptions!$B$15+Assumptions!$B$17))+Staffing!$E$5:$E$23+ABS(Staffing!$D$5:$D$23*((M12+M13)/(Assumptions!$B$15+Assumptions!$B$17))-Staffing!$E$5:$E$23))/2)*Staffing!$I$5:$I$23*(1+Assumptions!$B$36*Staffing!$J$5:$J$23))/12 -> 6608.3333 | ... AO26: =SUMPRODUCT((Staffing!$F$5:$F$23<=AO4)*(Staffing!$C$5:$C$23="Day program")*((Staffing!$D$5:$D$23*((AO12+AO13)/(Assumptions!$B$15+Assumptions!$B$17))+Staffing!$E$5:$E$23+ABS(Staffing!$D$5:$D$23*((AO12+AO13)/(Assumptions!$B$15+Assumptions!$B$17))-Staffing!$E$5:$E$23))/2)*Staffing!$I$5:$I$23*(1+Assumptions!$B$36*Staffing!$J$5:$J$23))/12 -> 13216.667
A27: Outpatient census-driven roles | F27: =SUMPRODUCT((Staffing!$F$5:$F$23<=F4)*(Staffing!$C$5:$C$23="Outpatient")*((Staffing!$D$5:$D$23*(F14/Assumptions!$B$19)+Staffing!$E$5:$E$23+ABS(Staffing!$D$5:$D$23*(F14/Assumptions!$B$19)-Staffing!$E$5:$E$23))/2)*Staffing!$I$5:$I$23*(1+Assumptions!$B$36*Staffing!$J$5:$J$23))/12 -> 0 | G27: =SUMPRODUCT((Staffing!$F$5:$F$23<=G4)*(Staffing!$C$5:$C$23="Outpatient")*((Staffing!$D$5:$D$23*(G14/Assumptions!$B$19)+Staffing!$E$5:$E$23+ABS(Staffing!$D$5:$D$23*(G14/Assumptions!$B$19)-Staffing!$E$5:$E$23))/2)*Staffing!$I$5:$I$23*(1+Assumptions!$B$36*Staffing!$J$5:$J$23))/12 -> 0 | H27: =SUMPRODUCT((Staffing!$F$5:$F$23<=H4)*(Staffing!$C$5:$C$23="Outpatient")*((Staffing!$D$5:$D$23*(H14/Assumptions!$B$19)+Staffing!$E$5:$E$23+ABS(Staffing!$D$5:$D$23*(H14/Assumptions!$B$19)-Staffing!$E$5:$E$23))/2)*Staffing!$I$5:$I$23*(1+Assumptions!$B$36*Staffing!$J$5:$J$23))/12 -> 0 | I27: =SUMPRODUCT((Staffing!$F$5:$F$23<=I4)*(Staffing!$C$5:$C$23="Outpatient")*((Staffing!$D$5:$D$23*(I14/Assumptions!$B$19)+Staffing!$E$5:$E$23+ABS(Staffing!$D$5:$D$23*(I14/Assumptions!$B$19)-Staffing!$E$5:$E$23))/2)*Staffing!$I$5:$I$23*(1+Assumptions!$B$36*Staffing!$J$5:$J$23))/12 -> 0 | J27: =SUMPRODUCT((Staffing!$F$5:$F$23<=J4)*(Staffing!$C$5:$C$23="Outpatient")*((Staffing!$D$5:$D$23*(J14/Assumptions!$B$19)+Staffing!$E$5:$E$23+ABS(Staffing!$D$5:$D$23*(J14/Assumptions!$B$19)-Staffing!$E$5:$E$23))/2)*Staffing!$I$5:$I$23*(1+Assumptions!$B$36*Staffing!$J$5:$J$23))/12 -> 0 | K27: =SUMPRODUCT((Staffing!$F$5:$F$23<=K4)*(Staffing!$C$5:$C$23="Outpatient")*((Staffing!$D$5:$D$23*(K14/Assumptions!$B$19)+Staffing!$E$5:$E$23+ABS(Staffing!$D$5:$D$23*(K14/Assumptions!$B$19)-Staffing!$E$5:$E$23))/2)*Staffing!$I$5:$I$23*(1+Assumptions!$B$36*Staffing!$J$5:$J$23))/12 -> 0 | L27: =SUMPRODUCT((Staffing!$F$5:$F$23<=L4)*(Staffing!$C$5:$C$23="Outpatient")*((Staffing!$D$5:$D$23*(L14/Assumptions!$B$19)+Staffing!$E$5:$E$23+ABS(Staffing!$D$5:$D$23*(L14/Assumptions!$B$19)-Staffing!$E$5:$E$23))/2)*Staffing!$I$5:$I$23*(1+Assumptions!$B$36*Staffing!$J$5:$J$23))/12 -> 0 | M27: =SUMPRODUCT((Staffing!$F$5:$F$23<=M4)*(Staffing!$C$5:$C$23="Outpatient")*((Staffing!$D$5:$D$23*(M14/Assumptions!$B$19)+Staffing!$E$5:$E$23+ABS(Staffing!$D$5:$D$23*(M14/Assumptions!$B$19)-Staffing!$E$5:$E$23))/2)*Staffing!$I$5:$I$23*(1+Assumptions!$B$36*Staffing!$J$5:$J$23))/12 -> 0 | ... AO27: =SUMPRODUCT((Staffing!$F$5:$F$23<=AO4)*(Staffing!$C$5:$C$23="Outpatient")*((Staffing!$D$5:$D$23*(AO14/Assumptions!$B$19)+Staffing!$E$5:$E$23+ABS(Staffing!$D$5:$D$23*(AO14/Assumptions!$B$19)-Staffing!$E$5:$E$23))/2)*Staffing!$I$5:$I$23*(1+Assumptions!$B$36*Staffing!$J$5:$J$23))/12 -> 0
A28: Total payroll incl. burden, PRN/OT and inflation | F28: =SUM(F24:F27)*F7*(1+Assumptions!$B$37) -> 22366.667 | G28: =SUM(G24:G27)*G7*(1+Assumptions!$B$37) -> 22366.667 | H28: =SUM(H24:H27)*H7*(1+Assumptions!$B$37) -> 42496.667 | I28: =SUM(I24:I27)*I7*(1+Assumptions!$B$37) -> 54239.167 | J28: =SUM(J24:J27)*J7*(1+Assumptions!$B$37) -> 202820.93 | K28: =SUM(K24:K27)*K7*(1+Assumptions!$B$37) -> 202820.93 | L28: =SUM(L24:L27)*L7*(1+Assumptions!$B$37) -> 202820.93 | M28: =SUM(M24:M27)*M7*(1+Assumptions!$B$37) -> 210090.1 | ... AO28: =SUM(AO24:AO27)*AO7*(1+Assumptions!$B$37) -> 238950.96
A29: OPERATING EXPENSES
A30: Rent | F30: =IF(F6>=0,Assumptions!$B$39*F7,IF(F4>=Assumptions!$B$41,Assumptions!$B$39*Assumptions!$B$40,0)) -> 0 | G30: =IF(G6>=0,Assumptions!$B$39*G7,IF(G4>=Assumptions!$B$41,Assumptions!$B$39*Assumptions!$B$40,0)) -> 0 | H30: =IF(H6>=0,Assumptions!$B$39*H7,IF(H4>=Assumptions!$B$41,Assumptions!$B$39*Assumptions!$B$40,0)) -> 22500 | I30: =IF(I6>=0,Assumptions!$B$39*I7,IF(I4>=Assumptions!$B$41,Assumptions!$B$39*Assumptions!$B$40,0)) -> 22500 | J30: =IF(J6>=0,Assumptions!$B$39*J7,IF(J4>=Assumptions!$B$41,Assumptions!$B$39*Assumptions!$B$40,0)) -> 22500 | K30: =IF(K6>=0,Assumptions!$B$39*K7,IF(K4>=Assumptions!$B$41,Assumptions!$B$39*Assumptions!$B$40,0)) -> 45000 | L30: =IF(L6>=0,Assumptions!$B$39*L7,IF(L4>=Assumptions!$B$41,Assumptions!$B$39*Assumptions!$B$40,0)) -> 45000 | M30: =IF(M6>=0,Assumptions!$B$39*M7,IF(M4>=Assumptions!$B$41,Assumptions!$B$39*Assumptions!$B$40,0)) -> 45000 | ... AO30: =IF(AO6>=0,Assumptions!$B$39*AO7,IF(AO4>=Assumptions!$B$41,Assumptions!$B$39*Assumptions!$B$40,0)) -> 47740.5
A31: Utilities | F31: =IF(F6>=0,Assumptions!$B$42*F7,IF(F4>=Assumptions!$B$44,Assumptions!$B$43,0)) -> 0 | G31: =IF(G6>=0,Assumptions!$B$42*G7,IF(G4>=Assumptions!$B$44,Assumptions!$B$43,0)) -> 0 | H31: =IF(H6>=0,Assumptions!$B$42*H7,IF(H4>=Assumptions!$B$44,Assumptions!$B$43,0)) -> 0 | I31: =IF(I6>=0,Assumptions!$B$42*I7,IF(I4>=Assumptions!$B$44,Assumptions!$B$43,0)) -> 4000 | J31: =IF(J6>=0,Assumptions!$B$42*J7,IF(J4>=Assumptions!$B$44,Assumptions!$B$43,0)) -> 4000 | K31: =IF(K6>=0,Assumptions!$B$42*K7,IF(K4>=Assumptions!$B$44,Assumptions!$B$43,0)) -> 12000 | L31: =IF(L6>=0,Assumptions!$B$42*L7,IF(L4>=Assumptions!$B$44,Assumptions!$B$43,0)) -> 12000 | M31: =IF(M6>=0,Assumptions!$B$42*M7,IF(M4>=Assumptions!$B$44,Assumptions!$B$43,0)) -> 12000 | ... AO31: =IF(AO6>=0,Assumptions!$B$42*AO7,IF(AO4>=Assumptions!$B$44,Assumptions!$B$43,0)) -> 12730.8
A32: Food | F32: =F11*Assumptions!$B$45 -> 0 | G32: =G11*Assumptions!$B$45 -> 0 | H32: =H11*Assumptions!$B$45 -> 0 | I32: =I11*Assumptions!$B$45 -> 0 | J32: =J11*Assumptions!$B$45 -> 0 | K32: =K11*Assumptions!$B$45 -> 1824 | L32: =L11*Assumptions!$B$45 -> 3040 | M32: =M11*Assumptions!$B$45 -> 4256 | ... AO32: =AO11*Assumptions!$B$45 -> 9120
A33: Medical and program supplies | F33: =F11*Assumptions!$B$46+(F12*Assumptions!$B$9+F13*Assumptions!$B$10)*Assumptions!$B$47 -> 0 | G33: =G11*Assumptions!$B$46+(G12*Assumptions!$B$9+G13*Assumptions!$B$10)*Assumptions!$B$47 -> 0 | H33: =H11*Assumptions!$B$46+(H12*Assumptions!$B$9+H13*Assumptions!$B$10)*Assumptions!$B$47 -> 0 | I33: =I11*Assumptions!$B$46+(I12*Assumptions!$B$9+I13*Assumptions!$B$10)*Assumptions!$B$47 -> 0 | J33: =J11*Assumptions!$B$46+(J12*Assumptions!$B$9+J13*Assumptions!$B$10)*Assumptions!$B$47 -> 0 | K33: =K11*Assumptions!$B$46+(K12*Assumptions!$B$9+K13*Assumptions!$B$10)*Assumptions!$B$47 -> 1824 | L33: =L11*Assumptions!$B$46+(L12*Assumptions!$B$9+L13*Assumptions!$B$10)*Assumptions!$B$47 -> 3040 | M33: =M11*Assumptions!$B$46+(M12*Assumptions!$B$9+M13*Assumptions!$B$10)*Assumptions!$B$47 -> 4321.1 | ... AO33: =AO11*Assumptions!$B$46+(AO12*Assumptions!$B$9+AO13*Assumptions!$B$10)*Assumptions!$B$47 -> 10159.8
A34: Experiential and activity supplies | F34: =IF(F6>=0,Assumptions!$B$48,0) -> 0 | G34: =IF(G6>=0,Assumptions!$B$48,0) -> 0 | H34: =IF(H6>=0,Assumptions!$B$48,0) -> 0 | I34: =IF(I6>=0,Assumptions!$B$48,0) -> 0 | J34: =IF(J6>=0,Assumptions!$B$48,0) -> 0 | K34: =IF(K6>=0,Assumptions!$B$48,0) -> 3000 | L34: =IF(L6>=0,Assumptions!$B$48,0) -> 3000 | M34: =IF(M6>=0,Assumptions!$B$48,0) -> 3000 | ... AO34: =IF(AO6>=0,Assumptions!$B$48,0) -> 3000
A35: Contracted wellness services | F35: =IF(F6>=0,Assumptions!$B$49,0) -> 0 | G35: =IF(G6>=0,Assumptions!$B$49,0) -> 0 | H35: =IF(H6>=0,Assumptions!$B$49,0) -> 0 | I35: =IF(I6>=0,Assumptions!$B$49,0) -> 0 | J35: =IF(J6>=0,Assumptions!$B$49,0) -> 0 | K35: =IF(K6>=0,Assumptions!$B$49,0) -> 8000 | L35: =IF(L6>=0,Assumptions!$B$49,0) -> 8000 | M35: =IF(M6>=0,Assumptions!$B$49,0) -> 8000 | ... AO35: =IF(AO6>=0,Assumptions!$B$49,0) -> 8000
A36: Medical director stipend | F36: =IF(F4>=Assumptions!$B$51,Assumptions!$B$50,0) -> 0 | G36: =IF(G4>=Assumptions!$B$51,Assumptions!$B$50,0) -> 0 | H36: =IF(H4>=Assumptions!$B$51,Assumptions!$B$50,0) -> 5000 | I36: =IF(I4>=Assumptions!$B$51,Assumptions!$B$50,0) -> 5000 | J36: =IF(J4>=Assumptions!$B$51,Assumptions!$B$50,0) -> 5000 | K36: =IF(K4>=Assumptions!$B$51,Assumptions!$B$50,0) -> 5000 | L36: =IF(L4>=Assumptions!$B$51,Assumptions!$B$50,0) -> 5000 | M36: =IF(M4>=Assumptions!$B$51,Assumptions!$B$50,0) -> 5000 | ... AO36: =IF(AO4>=Assumptions!$B$51,Assumptions!$B$50,0) -> 5000
A37: Insurance | F37: =IF(F4>=Assumptions!$B$53,Assumptions!$B$52,0) -> 0 | G37: =IF(G4>=Assumptions!$B$53,Assumptions!$B$52,0) -> 0 | H37: =IF(H4>=Assumptions!$B$53,Assumptions!$B$52,0) -> 0 | I37: =IF(I4>=Assumptions!$B$53,Assumptions!$B$52,0) -> 12500 | J37: =IF(J4>=Assumptions!$B$53,Assumptions!$B$52,0) -> 12500 | K37: =IF(K4>=Assumptions!$B$53,Assumptions!$B$52,0) -> 12500 | L37: =IF(L4>=Assumptions!$B$53,Assumptions!$B$52,0) -> 12500 | M37: =IF(M4>=Assumptions!$B$53,Assumptions!$B$52,0) -> 12500 | ... AO37: =IF(AO4>=Assumptions!$B$53,Assumptions!$B$52,0) -> 12500
A38: Technology and EHR | F38: =IF(F4>=Assumptions!$B$55,Assumptions!$B$54,0) -> 0 | G38: =IF(G4>=Assumptions!$B$55,Assumptions!$B$54,0) -> 0 | H38: =IF(H4>=Assumptions!$B$55,Assumptions!$B$54,0) -> 10000 | I38: =IF(I4>=Assumptions!$B$55,Assumptions!$B$54,0) -> 10000 | J38: =IF(J4>=Assumptions!$B$55,Assumptions!$B$54,0) -> 10000 | K38: =IF(K4>=Assumptions!$B$55,Assumptions!$B$54,0) -> 10000 | L38: =IF(L4>=Assumptions!$B$55,Assumptions!$B$54,0) -> 10000 | M38: =IF(M4>=Assumptions!$B$55,Assumptions!$B$54,0) -> 10000 | ... AO38: =IF(AO4>=Assumptions!$B$55,Assumptions!$B$54,0) -> 10000
A39: Clearinghouse and billing software | F39: =IF(F6>=0,Assumptions!$B$56,0) -> 0 | G39: =IF(G6>=0,Assumptions!$B$56,0) -> 0 | H39: =IF(H6>=0,Assumptions!$B$56,0) -> 0 | I39: =IF(I6>=0,Assumptions!$B$56,0) -> 0 | J39: =IF(J6>=0,Assumptions!$B$56,0) -> 0 | K39: =IF(K6>=0,Assumptions!$B$56,0) -> 2500 | L39: =IF(L6>=0,Assumptions!$B$56,0) -> 2500 | M39: =IF(M6>=0,Assumptions!$B$56,0) -> 2500 | ... AO39: =IF(AO6>=0,Assumptions!$B$56,0) -> 2500
A40: Paid media (Google, Meta, directories) | F40: =IF(F6>=0,Assumptions!$B$57,IF(F4>=Assumptions!$B$59,Assumptions!$B$58,0)) -> 0 | G40: =IF(G6>=0,Assumptions!$B$57,IF(G4>=Assumptions!$B$59,Assumptions!$B$58,0)) -> 0 | H40: =IF(H6>=0,Assumptions!$B$57,IF(H4>=Assumptions!$B$59,Assumptions!$B$58,0)) -> 0 | I40: =IF(I6>=0,Assumptions!$B$57,IF(I4>=Assumptions!$B$59,Assumptions!$B$58,0)) -> 10000 | J40: =IF(J6>=0,Assumptions!$B$57,IF(J4>=Assumptions!$B$59,Assumptions!$B$58,0)) -> 10000 | K40: =IF(K6>=0,Assumptions!$B$57,IF(K4>=Assumptions!$B$59,Assumptions!$B$58,0)) -> 25000 | L40: =IF(L6>=0,Assumptions!$B$57,IF(L4>=Assumptions!$B$59,Assumptions!$B$58,0)) -> 25000 | M40: =IF(M6>=0,Assumptions!$B$57,IF(M4>=Assumptions!$B$59,Assumptions!$B$58,0)) -> 25000 | ... AO40: =IF(AO6>=0,Assumptions!$B$57,IF(AO4>=Assumptions!$B$59,Assumptions!$B$58,0)) -> 25000
...

Sheet Base Monthly
A1: EverBloom: monthly model, Base case
A2: All values in $ unless noted. Columns C-E are blank padding so collection lags work in the first months.
C3: (pad) | D3: (pad) | E3: (pad)
A4: Month | F4: 1 | G4: 2 | H4: 3 | I4: 4 | J4: 5 | K4: 6 | L4: 7 | M4: 8 | N4: 9 | O4: 10 | P4: 11 | Q4: 12 | R4: 13 | S4: 14 | T4: 15 | U4: 16 | V4: 17 | W4: 18 | X4: 19 | Y4: 20 | Z4: 21 | AA4: 22 | AB4: 23 | AC4: 24 | AD4: 25 | AE4: 26 | AF4: 27 | AG4: 28 | AH4: 29 | AI4: 30 | AJ4: 31 | AK4: 32 | AL4: 33 | AM4: 34 | AN4: 35 | AO4: 36
A5: Year | F5: =ROUNDUP(F4/12,0) -> 1 | G5: =ROUNDUP(G4/12,0) -> 1 | H5: =ROUNDUP(H4/12,0) -> 1 | I5: =ROUNDUP(I4/12,0) -> 1 | J5: =ROUNDUP(J4/12,0) -> 1 | K5: =ROUNDUP(K4/12,0) -> 1 | L5: =ROUNDUP(L4/12,0) -> 1 | M5: =ROUNDUP(M4/12,0) -> 1 | ... AO5: =ROUNDUP(AO4/12,0) -> 3
A6: Months since opening | F6: =F4-Assumptions!$C$7 -> -5 | G6: =G4-Assumptions!$C$7 -> -4 | H6: =H4-Assumptions!$C$7 -> -3 | I6: =I4-Assumptions!$C$7 -> -2 | J6: =J4-Assumptions!$C$7 -> -1 | K6: =K4-Assumptions!$C$7 -> 0 | L6: =L4-Assumptions!$C$7 -> 1 | M6: =M4-Assumptions!$C$7 -> 2 | ... AO6: =AO4-Assumptions!$C$7 -> 30
A7: Cost escalator | F7: =(1+Assumptions!$C$28)^(F5-1) -> 1 | G7: =(1+Assumptions!$C$28)^(G5-1) -> 1 | H7: =(1+Assumptions!$C$28)^(H5-1) -> 1 | I7: =(1+Assumptions!$C$28)^(I5-1) -> 1 | J7: =(1+Assumptions!$C$28)^(J5-1) -> 1 | K7: =(1+Assumptions!$C$28)^(K5-1) -> 1 | L7: =(1+Assumptions!$C$28)^(L5-1) -> 1 | M7: =(1+Assumptions!$C$28)^(M5-1) -> 1 | ... AO7: =(1+Assumptions!$C$28)^(AO5-1) -> 1.0609
A8: Rate escalator | F8: =IF(F4>24,1+Assumptions!$C$27,1) -> 1 | G8: =IF(G4>24,1+Assumptions!$C$27,1) -> 1 | H8: =IF(H4>24,1+Assumptions!$C$27,1) -> 1 | I8: =IF(I4>24,1+Assumptions!$C$27,1) -> 1 | J8: =IF(J4>24,1+Assumptions!$C$27,1) -> 1 | K8: =IF(K4>24,1+Assumptions!$C$27,1) -> 1 | L8: =IF(L4>24,1+Assumptions!$C$27,1) -> 1 | M8: =IF(M4>24,1+Assumptions!$C$27,1) -> 1 | ... AO8: =IF(AO4>24,1+Assumptions!$C$27,1) -> 1.03
A9: VOLUMES
A10: Residential occupancy | F10: =IF(F6<0,0,IF(F6<11,INDEX(Assumptions!$C$69:$C$79,F6+1),IF(F4>24,Assumptions!$C$14,Assumptions!$C$13))) -> 0 | G10: =IF(G6<0,0,IF(G6<11,INDEX(Assumptions!$C$69:$C$79,G6+1),IF(G4>24,Assumptions!$C$14,Assumptions!$C$13))) -> 0 | H10: =IF(H6<0,0,IF(H6<11,INDEX(Assumptions!$C$69:$C$79,H6+1),IF(H4>24,Assumptions!$C$14,Assumptions!$C$13))) -> 0 | I10: =IF(I6<0,0,IF(I6<11,INDEX(Assumptions!$C$69:$C$79,I6+1),IF(I4>24,Assumptions!$C$14,Assumptions!$C$13))) -> 0 | J10: =IF(J6<0,0,IF(J6<11,INDEX(Assumptions!$C$69:$C$79,J6+1),IF(J4>24,Assumptions!$C$14,Assumptions!$C$13))) -> 0 | K10: =IF(K6<0,0,IF(K6<11,INDEX(Assumptions!$C$69:$C$79,K6+1),IF(K4>24,Assumptions!$C$14,Assumptions!$C$13))) -> 0.25 | L10: =IF(L6<0,0,IF(L6<11,INDEX(Assumptions!$C$69:$C$79,L6+1),IF(L4>24,Assumptions!$C$14,Assumptions!$C$13))) -> 0.4 | M10: =IF(M6<0,0,IF(M6<11,INDEX(Assumptions!$C$69:$C$79,M6+1),IF(M4>24,Assumptions!$C$14,Assumptions!$C$13))) -> 0.5 | ... AO10: =IF(AO6<0,0,IF(AO6<11,INDEX(Assumptions!$C$69:$C$79,AO6+1),IF(AO4>24,Assumptions!$C$14,Assumptions!$C$13))) -> 0.85
A11: Residential patient days | F11: =Assumptions!$C$6*F10*Assumptions!$C$8 -> 0 | G11: =Assumptions!$C$6*G10*Assumptions!$C$8 -> 0 | H11: =Assumptions!$C$6*H10*Assumptions!$C$8 -> 0 | I11: =Assumptions!$C$6*I10*Assumptions!$C$8 -> 0 | J11: =Assumptions!$C$6*J10*Assumptions!$C$8 -> 0 | K11: =Assumptions!$C$6*K10*Assumptions!$C$8 -> 152 | L11: =Assumptions!$C$6*L10*Assumptions!$C$8 -> 243.2 | M11: =Assumptions!$C$6*M10*Assumptions!$C$8 -> 304 | ... AO11: =Assumptions!$C$6*AO10*Assumptions!$C$8 -> 516.8
A12: PHP average daily census | F12: =IF(F6-Assumptions!$C$21<0,0,Assumptions!$C$15*MIN(1,(F6-Assumptions!$C$21+1)/Assumptions!$C$22)) -> 0 | G12: =IF(G6-Assumptions!$C$21<0,0,Assumptions!$C$15*MIN(1,(G6-Assumptions!$C$21+1)/Assumptions!$C$22)) -> 0 | H12: =IF(H6-Assumptions!$C$21<0,0,Assumptions!$C$15*MIN(1,(H6-Assumptions!$C$21+1)/Assumptions!$C$22)) -> 0 | I12: =IF(I6-Assumptions!$C$21<0,0,Assumptions!$C$15*MIN(1,(I6-Assumptions!$C$21+1)/Assumptions!$C$22)) -> 0 | J12: =IF(J6-Assumptions!$C$21<0,0,Assumptions!$C$15*MIN(1,(J6-Assumptions!$C$21+1)/Assumptions!$C$22)) -> 0 | K12: =IF(K6-Assumptions!$C$21<0,0,Assumptions!$C$15*MIN(1,(K6-Assumptions!$C$21+1)/Assumptions!$C$22)) -> 0 | L12: =IF(L6-Assumptions!$C$21<0,0,Assumptions!$C$15*MIN(1,(L6-Assumptions!$C$21+1)/Assumptions!$C$22)) -> 0 | M12: =IF(M6-Assumptions!$C$21<0,0,Assumptions!$C$15*MIN(1,(M6-Assumptions!$C$21+1)/Assumptions!$C$22)) -> 1.5 | ... AO12: =IF(AO6-Assumptions!$C$21<0,0,Assumptions!$C$15*MIN(1,(AO6-Assumptions!$C$21+1)/Assumptions!$C$22)) -> 12
A13: IOP average daily census | F13: =IF(F6-Assumptions!$C$23<0,0,Assumptions!$C$17*MIN(1,(F6-Assumptions!$C$23+1)/Assumptions!$C$24)) -> 0 | G13: =IF(G6-Assumptions!$C$23<0,0,Assumptions!$C$17*MIN(1,(G6-Assumptions!$C$23+1)/Assumptions!$C$24)) -> 0 | H13: =IF(H6-Assumptions!$C$23<0,0,Assumptions!$C$17*MIN(1,(H6-Assumptions!$C$23+1)/Assumptions!$C$24)) -> 0 | I13: =IF(I6-Assumptions!$C$23<0,0,Assumptions!$C$17*MIN(1,(I6-Assumptions!$C$23+1)/Assumptions!$C$24)) -> 0 | J13: =IF(J6-Assumptions!$C$23<0,0,Assumptions!$C$17*MIN(1,(J6-Assumptions!$C$23+1)/Assumptions!$C$24)) -> 0 | K13: =IF(K6-Assumptions!$C$23<0,0,Assumptions!$C$17*MIN(1,(K6-Assumptions!$C$23+1)/Assumptions!$C$24)) -> 0 | L13: =IF(L6-Assumptions!$C$23<0,0,Assumptions!$C$17*MIN(1,(L6-Assumptions!$C$23+1)/Assumptions!$C$24)) -> 0 | M13: =IF(M6-Assumptions!$C$23<0,0,Assumptions!$C$17*MIN(1,(M6-Assumptions!$C$23+1)/Assumptions!$C$24)) -> 0 | ... AO13: =IF(AO6-Assumptions!$C$23<0,0,Assumptions!$C$17*MIN(1,(AO6-Assumptions!$C$23+1)/Assumptions!$C$24)) -> 15
A14: Outpatient visits | F14: =IF(F6-Assumptions!$C$25<0,0,Assumptions!$C$19*MIN(1,(F6-Assumptions!$C$25+1)/Assumptions!$C$26)) -> 0 | G14: =IF(G6-Assumptions!$C$25<0,0,Assumptions!$C$19*MIN(1,(G6-Assumptions!$C$25+1)/Assumptions!$C$26)) -> 0 | H14: =IF(H6-Assumptions!$C$25<0,0,Assumptions!$C$19*MIN(1,(H6-Assumptions!$C$25+1)/Assumptions!$C$26)) -> 0 | I14: =IF(I6-Assumptions!$C$25<0,0,Assumptions!$C$19*MIN(1,(I6-Assumptions!$C$25+1)/Assumptions!$C$26)) -> 0 | J14: =IF(J6-Assumptions!$C$25<0,0,Assumptions!$C$19*MIN(1,(J6-Assumptions!$C$25+1)/Assumptions!$C$26)) -> 0 | K14: =IF(K6-Assumptions!$C$25<0,0,Assumptions!$C$19*MIN(1,(K6-Assumptions!$C$25+1)/Assumptions!$C$26)) -> 0 | L14: =IF(L6-Assumptions!$C$25<0,0,Assumptions!$C$19*MIN(1,(L6-Assumptions!$C$25+1)/Assumptions!$C$26)) -> 0 | M14: =IF(M6-Assumptions!$C$25<0,0,Assumptions!$C$19*MIN(1,(M6-Assumptions!$C$25+1)/Assumptions!$C$26)) -> 0 | ... AO14: =IF(AO6-Assumptions!$C$25<0,0,Assumptions!$C$19*MIN(1,(AO6-Assumptions!$C$25+1)/Assumptions!$C$26)) -> 200
A15: REVENUE (billed, net of contractual adjustments)
A16: Residential | F16: =F11*Assumptions!$C$12*F8 -> 0 | G16: =G11*Assumptions!$C$12*G8 -> 0 | H16: =H11*Assumptions!$C$12*H8 -> 0 | I16: =I11*Assumptions!$C$12*I8 -> 0 | J16: =J11*Assumptions!$C$12*J8 -> 0 | K16: =K11*Assumptions!$C$12*K8 -> 167200 | L16: =L11*Assumptions!$C$12*L8 -> 267520 | M16: =M11*Assumptions!$C$12*M8 -> 334400 | ... AO16: =AO11*Assumptions!$C$12*AO8 -> 585534.4
A17: PHP | F17: =F12*Assumptions!$C$9*Assumptions!$C$16*F8 -> 0 | G17: =G12*Assumptions!$C$9*Assumptions!$C$16*G8 -> 0 | H17: =H12*Assumptions!$C$9*Assumptions!$C$16*H8 -> 0 | I17: =I12*Assumptions!$C$9*Assumptions!$C$16*I8 -> 0 | J17: =J12*Assumptions!$C$9*Assumptions!$C$16*J8 -> 0 | K17: =K12*Assumptions!$C$9*Assumptions!$C$16*K8 -> 0 | L17: =L12*Assumptions!$C$9*Assumptions!$C$16*L8 -> 0 | M17: =M12*Assumptions!$C$9*Assumptions!$C$16*M8 -> 17902.5 | ... AO17: =AO12*Assumptions!$C$9*Assumptions!$C$16*AO8 -> 147516.6
A18: IOP | F18: =F13*Assumptions!$C$10*Assumptions!$C$18*F8 -> 0 | G18: =G13*Assumptions!$C$10*Assumptions!$C$18*G8 -> 0 | H18: =H13*Assumptions!$C$10*Assumptions!$C$18*H8 -> 0 | I18: =I13*Assumptions!$C$10*Assumptions!$C$18*I8 -> 0 | J18: =J13*Assumptions!$C$10*Assumptions!$C$18*J8 -> 0 | K18: =K13*Assumptions!$C$10*Assumptions!$C$18*K8 -> 0 | L18: =L13*Assumptions!$C$10*Assumptions!$C$18*L8 -> 0 | M18: =M13*Assumptions!$C$10*Assumptions!$C$18*M8 -> 0 | ... AO18: =AO13*Assumptions!$C$10*Assumptions!$C$18*AO8 -> 73503.375
A19: Outpatient | F19: =F14*Assumptions!$C$20*F8 -> 0 | G19: =G14*Assumptions!$C$20*G8 -> 0 | H19: =H14*Assumptions!$C$20*H8 -> 0 | I19: =I14*Assumptions!$C$20*I8 -> 0 | J19: =J14*Assumptions!$C$20*J8 -> 0 | K19: =K14*Assumptions!$C$20*K8 -> 0 | L19: =L14*Assumptions!$C$20*L8 -> 0 | M19: =M14*Assumptions!$C$20*M8 -> 0 | ... AO19: =AO14*Assumptions!$C$20*AO8 -> 30900
A20: Gross billed revenue | F20: =SUM(F16:F19) -> 0 | G20: =SUM(G16:G19) -> 0 | H20: =SUM(H16:H19) -> 0 | I20: =SUM(I16:I19) -> 0 | J20: =SUM(J16:J19) -> 0 | K20: =SUM(K16:K19) -> 167200 | L20: =SUM(L16:L19) -> 267520 | M20: =SUM(M16:M19) -> 352302.5 | ... AO20: =SUM(AO16:AO19) -> 837454.38
A21: Less denials and bad debt | F21: =-F20*Assumptions!$C$30 -> 0 | G21: =-G20*Assumptions!$C$30 -> 0 | H21: =-H20*Assumptions!$C$30 -> 0 | I21: =-I20*Assumptions!$C$30 -> 0 | J21: =-J20*Assumptions!$C$30 -> 0 | K21: =-K20*Assumptions!$C$30 -> -13376 | L21: =-L20*Assumptions!$C$30 -> -21401.6 | M21: =-M20*Assumptions!$C$30 -> -28184.2 | ... AO21: =-AO20*Assumptions!$C$30 -> -66996.35
A22: Net revenue | C22: 0 | D22: 0 | E22: 0 | F22: =F20+F21 -> 0 | G22: =G20+G21 -> 0 | H22: =H20+H21 -> 0 | I22: =I20+I21 -> 0 | J22: =J20+J21 -> 0 | K22: =K20+K21 -> 153824 | L22: =L20+L21 -> 246118.4 | M22: =M20+M21 -> 324118.3 | ... AO22: =AO20+AO21 -> 770458.03
A23: PAYROLL
A24: Fixed roles (leadership, RCM, admissions, marketing, nursing, support) | F24: =SUMPRODUCT((Staffing!$F$5:$F$23<=F4)*(Staffing!$C$5:$C$23="Fixed")*Staffing!$D$5:$D$23*Staffing!$I$5:$I$23*(1+Assumptions!$B$36*Staffing!$J$5:$J$23))/12 -> 20333.333 | G24: =SUMPRODUCT((Staffing!$F$5:$F$23<=G4)*(Staffing!$C$5:$C$23="Fixed")*Staffing!$D$5:$D$23*Staffing!$I$5:$I$23*(1+Assumptions!$B$36*Staffing!$J$5:$J$23))/12 -> 20333.333 | H24: =SUMPRODUCT((Staffing!$F$5:$F$23<=H4)*(Staffing!$C$5:$C$23="Fixed")*Staffing!$D$5:$D$23*Staffing!$I$5:$I$23*(1+Assumptions!$B$36*Staffing!$J$5:$J$23))/12 -> 38633.333 | I24: =SUMPRODUCT((Staffing!$F$5:$F$23<=I4)*(Staffing!$C$5:$C$23="Fixed")*Staffing!$D$5:$D$23*Staffing!$I$5:$I$23*(1+Assumptions!$B$36*Staffing!$J$5:$J$23))/12 -> 49308.333 | J24: =SUMPRODUCT((Staffing!$F$5:$F$23<=J4)*(Staffing!$C$5:$C$23="Fixed")*Staffing!$D$5:$D$23*Staffing!$I$5:$I$23*(1+Assumptions!$B$36*Staffing!$J$5:$J$23))/12 -> 177774.33 | K24: =SUMPRODUCT((Staffing!$F$5:$F$23<=K4)*(Staffing!$C$5:$C$23="Fixed")*Staffing!$D$5:$D$23*Staffing!$I$5:$I$23*(1+Assumptions!$B$36*Staffing!$J$5:$J$23))/12 -> 177774.33 | L24: =SUMPRODUCT((Staffing!$F$5:$F$23<=L4)*(Staffing!$C$5:$C$23="Fixed")*Staffing!$D$5:$D$23*Staffing!$I$5:$I$23*(1+Assumptions!$B$36*Staffing!$J$5:$J$23))/12 -> 177774.33 | M24: =SUMPRODUCT((Staffing!$F$5:$F$23<=M4)*(Staffing!$C$5:$C$23="Fixed")*Staffing!$D$5:$D$23*Staffing!$I$5:$I$23*(1+Assumptions!$B$36*Staffing!$J$5:$J$23))/12 -> 177774.33 | ... AO24: =SUMPRODUCT((Staffing!$F$5:$F$23<=AO4)*(Staffing!$C$5:$C$23="Fixed")*Staffing!$D$5:$D$23*Staffing!$I$5:$I$23*(1+Assumptions!$B$36*Staffing!$J$5:$J$23))/12 -> 177774.33
